"use client"

import React from "react"
import { Button } from "@/components/ui/button"
import { Card, CardContent, CardDescription, CardHeader, CardTitle } from "@/components/ui/card"
import { AlertTriangle, RefreshCw } from "lucide-react"

interface ErrorBoundaryState {
  hasError: boolean
  error?: Error
}

interface ErrorBoundaryProps {
  children: React.ReactNode
  fallback?: React.ComponentType<ErrorFallbackProps>
}

interface ErrorFallbackProps {
  error: Error
  resetError: () => void
}

function DefaultErrorFallback({ error, resetError }: ErrorFallbackProps) {
  return (
    <div className="min-h-[400px] flex items-center justify-center p-4">
      <Card className="w-full max-w-md">
        <CardHeader className="text-center">
          <div className="mx-auto mb-4 flex h-12 w-12 items-center justify-center rounded-full bg-red-100">
            <AlertTriangle className="h-6 w-6 text-red-600" />
          </div>
          <CardTitle className="text-xl">Something went wrong</CardTitle>
          <CardDescription>
            We're sorry, but something unexpected happened. Please try again.
          </CardDescription>
        </CardHeader>
        <CardContent className="space-y-4">
          <details className="text-sm">
            <summary className="cursor-pointer text-muted-foreground hover:text-foreground">
              Error details
            </summary>
            <pre className="mt-2 whitespace-pre-wrap rounded bg-muted p-2 text-xs">
              {error.message}
            </pre>
          </details>
          <Button onClick={resetError} className="w-full">
            <RefreshCw className="mr-2 h-4 w-4" />
            Try again
          </Button>
        </CardContent>
      </Card>
    </div>
  )
}

export class ErrorBoundary extends React.Component<ErrorBoundaryProps, ErrorBoundaryState> {
  constructor(props: ErrorBoundaryProps) {
    super(props)
    this.state = { hasError: false }
  }

  static getDerivedStateFromError(error: Error): ErrorBoundaryState {
    return { hasError: true, error }
  }

  componentDidCatch(error: Error, errorInfo: React.ErrorInfo) {
    console.error("Error boundary caught an error:", error, errorInfo)
  }

  resetError = () => {
    this.setState({ hasError: false, error: undefined })
  }

  render() {
    if (this.state.hasError && this.state.error) {
      const FallbackComponent = this.props.fallback || DefaultErrorFallback
      return (
        <FallbackComponent
          error={this.state.error}
          resetError={this.resetError}
        />
      )
    }

    return this.props.children
  }
}

// Hook version for functional components
export function useErrorHandler() {
  return (error: Error, errorInfo?: { componentStack: string }) => {
    console.error("Error caught by error handler:", error, errorInfo)
    // Could send to error reporting service here
  }
}